Workbook

Sheet Лист7
A2: Корреспонденция | H2: 36 | I2: =VLOOKUP(H2,[1]техлист2!AF:AG,2,0) -> С.Петербург-Главн. - Высоково | J2: =VLOOKUP(I2,[1]техлист!D:E,2,0) -> Санкт-Петербург - Высоково
A3: Год | F3: 4.238 | H3: 3 | I3: =INDEX([1]техлист!M2:M9,MATCH(H3,[1]техлист!N2:N9,0)) -> 2030
A4: Целевая цена | B4: {=INDEX([1]техлист2!X8:AE51,H2,H3)} -> 7931 | F4: 2.875
A5: Билетная часть | B5: =40%*B4 -> 3172.4
A6: Плацкартная часть | B6: =60%*B4 -> 4758.6
B8: Цена расчет | C8: Цена ЦЭИ | D8: Цена ЖД | E8: Цена авиа | F8: Эластичность | G8: Коэфф эластичности | H8: Продано мест | I8: Всего | J8: Проверка
A9: Тариф Эконом | B9: =$B$5+$B$6*$B$17*G9 -> 4175.785 | C9: =INDEX([1]ЦЭИ_тарифы!$D$2:$AP$145,MATCH($J$2&A9,[1]ЦЭИ_тарифы!$C$2:$C$145,0),MATCH($I$3,[1]ЦЭИ_тарифы!$D$1:$AP$1,0)) -> 5346.8059 | D9: 6094 | E9: 5200 | F9: -1.4 | G9: =$F$3+$F$4*F9 -> 0.213 | H9: 90 | I9: 136 | J9: =IF(B9<C9,"✅","❌") -> ✅ | K9: =H9/I9 -> 0.66176471
A10: Тариф Комфорт | B10: =$B$5+$B$6*$B$17*G10 -> 7697.054 | C10: =INDEX([1]ЦЭИ_тарифы!$D$2:$AP$145,MATCH($J$2&A10,[1]ЦЭИ_тарифы!$C$2:$C$145,0),MATCH($I$3,[1]ЦЭИ_тарифы!$D$1:$AP$1,0)) -> 7349.1978 | D10: 8000 | E10: 8000 | F10: -1.14 | G10: =$F$3+$F$4*F10 -> 0.9605 | H10: 5 | I10: 230 | J10: =IF(B10<C10,"✅","❌") -> ❌ | K10: =H10/I10 -> 0.02173913
A11: Тариф Бизнес | B11: =$B$5+$B$6*$B$17*G11 -> 15687.626 | C11: =INDEX([1]ЦЭИ_тарифы!$D$2:$AP$145,MATCH($J$2&A11,[1]ЦЭИ_тарифы!$C$2:$C$145,0),MATCH($I$3,[1]ЦЭИ_тарифы!$D$1:$AP$1,0)) -> 15685.013 | D11: 20000 | E11: 20000 | F11: -0.55 | G11: =$F$3+$F$4*F11 -> 2.65675 | H11: 7 | I11: 68 | J11: =IF(B11<C11,"✅","❌") -> ❌ | K11: =H11/I11 -> 0.10294118
A12: Тариф Первый | B12: =$B$5+$B$6*$B$17*G12 -> 21782.13 | C12: =INDEX([1]ЦЭИ_тарифы!$D$2:$AP$145,MATCH($J$2&A12,[1]ЦЭИ_тарифы!$C$2:$C$145,0),MATCH($I$3,[1]ЦЭИ_тарифы!$D$1:$AP$1,0)) -> 24953.442 | D12: 32000 | F12: -0.1 | G12: =$F$3+$F$4*F12 -> 3.9505 | H12: 10 | I12: 18 | J12: =IF(B12<C12,"✅","❌") -> ✅ | K12: =H12/I12 -> 0.55555556
A13: средневзвешенная цена | B13: =SUMPRODUCT(B9:B12,H9:H12)/SUM(H9:H12) -> 6624.4696 | C13: =SUMPRODUCT(C9:C12,H9:H12)/SUM(H9:H12) -> 7832.9288 | H13: =SUM(H9:H12) -> 112 | I13: =SUM(I9:I12) -> 452
H14: =H13/I13 -> 0.24778761
A15: Коэфф факторные | B15: 0.8
A16: Коэфф матрицы (глубина/загрузка) | B16: =D33 -> 1.2374248
A17: Итого | B17: =B15*B16 -> 0.98993984
A18: глубина | B18: 8
A20: Матрица коэффициентов K (глубина × загрузка)
A21: Kmin | B21: 0.5
A22: Kmax | B22: 2.5
A23: α (вес загрузки) | B23: 0.6 | C23: вес влияния загрузки vs глубины
A24: гамма | B24: 1 | C24: вклад загрузки
A25: k | B25: 2 | C25: вклад глубины по экспоненте
L27: СРЗНАЧ(K_base,π) | M27: =SUMPRODUCT(B29:J36, C55:K62) -> 0
A28: Глубина / Загрузка | B28: 0–9% | C28: 10–19% | D28: 20–39% | E28: 40–49% | F28: 50–59% | G28: 60–69% | H28: 70–79% | I28: 80–89% | J28: 90–100% | K28: 1.01 | L28: 1.02 | M28: 1.03 | N28: 1.04 | O28: 1.05
A29: 0-1 | B29: =$B$21+($B$22-$B$21)*($B$23*POWER((COLUMN()-COLUMN($B$29)+1)/13,$B$24)+(1-$B$23)*(1-EXP(-$B$25*((8-(ROW()-ROW($B$29)+1))/7)))) -> 1.2840395 | C29: =$B$21+($B$22-$B$21)*($B$23*POWER((COLUMN()-COLUMN($B$29)+1)/13,$B$24)+(1-$B$23)*(1-EXP(-$B$25*((8-(ROW()-ROW($B$29)+1))/7)))) -> 1.3763472 | D29: =$B$21+($B$22-$B$21)*($B$23*POWER((COLUMN()-COLUMN($B$29)+1)/13,$B$24)+(1-$B$23)*(1-EXP(-$B$25*((8-(ROW()-ROW($B$29)+1))/7)))) -> 1.4686549 | E29: =$B$21+($B$22-$B$21)*($B$23*POWER((COLUMN()-COLUMN($B$29)+1)/13,$B$24)+(1-$B$23)*(1-EXP(-$B$25*((8-(ROW()-ROW($B$29)+1))/7)))) -> 1.5609625 | F29: =$B$21+($B$22-$B$21)*($B$23*POWER((COLUMN()-COLUMN($B$29)+1)/13,$B$24)+(1-$B$23)*(1-EXP(-$B$25*((8-(ROW()-ROW($B$29)+1))/7)))) -> 1.6532702 | G29: =$B$21+($B$22-$B$21)*($B$23*POWER((COLUMN()-COLUMN($B$29)+1)/13,$B$24)+(1-$B$23)*(1-EXP(-$B$25*((8-(ROW()-ROW($B$29)+1))/7)))) -> 1.7455779 | H29: =$B$21+($B$22-$B$21)*($B$23*POWER((COLUMN()-COLUMN($B$29)+1)/13,$B$24)+(1-$B$23)*(1-EXP(-$B$25*((8-(ROW()-ROW($B$29)+1))/7)))) -> 1.8378856 | I29: =$B$21+($B$22-$B$21)*($B$23*POWER((COLUMN()-COLUMN($B$29)+1)/13,$B$24)+(1-$B$23)*(1-EXP(-$B$25*((8-(ROW()-ROW($B$29)+1))/7)))) -> 1.9301933 | ... O29: =$B$21+($B$22-$B$21)*($B$23*POWER((COLUMN()-COLUMN($B$29)+1)/13,$B$24)+(1-$B$23)*(1-EXP(-$B$25*((8-(ROW()-ROW($B$29)+1))/7)))) -> 2.4840395
A30: 2-3 | B30: =$B$21+($B$22-$B$21)*($B$23*POWER((COLUMN()-COLUMN($B$29)+1)/13,$B$24)+(1-$B$23)*(1-EXP(-$B$25*((8-(ROW()-ROW($B$29)+1))/7)))) -> 1.2482338 | C30: =$B$21+($B$22-$B$21)*($B$23*POWER((COLUMN()-COLUMN($B$29)+1)/13,$B$24)+(1-$B$23)*(1-EXP(-$B$25*((8-(ROW()-ROW($B$29)+1))/7)))) -> 1.3405415 | D30: =$B$21+($B$22-$B$21)*($B$23*POWER((COLUMN()-COLUMN($B$29)+1)/13,$B$24)+(1-$B$23)*(1-EXP(-$B$25*((8-(ROW()-ROW($B$29)+1))/7)))) -> 1.4328492 | E30: =$B$21+($B$22-$B$21)*($B$23*POWER((COLUMN()-COLUMN($B$29)+1)/13,$B$24)+(1-$B$23)*(1-EXP(-$B$25*((8-(ROW()-ROW($B$29)+1))/7)))) -> 1.5251569 | F30: =$B$21+($B$22-$B$21)*($B$23*POWER((COLUMN()-COLUMN($B$29)+1)/13,$B$24)+(1-$B$23)*(1-EXP(-$B$25*((8-(ROW()-ROW($B$29)+1))/7)))) -> 1.6174646 | G30: =$B$21+($B$22-$B$21)*($B$23*POWER((COLUMN()-COLUMN($B$29)+1)/13,$B$24)+(1-$B$23)*(1-EXP(-$B$25*((8-(ROW()-ROW($B$29)+1))/7)))) -> 1.7097723 | H30: =$B$21+($B$22-$B$21)*($B$23*POWER((COLUMN()-COLUMN($B$29)+1)/13,$B$24)+(1-$B$23)*(1-EXP(-$B$25*((8-(ROW()-ROW($B$29)+1))/7)))) -> 1.80208 | I30: =$B$21+($B$22-$B$21)*($B$23*POWER((COLUMN()-COLUMN($B$29)+1)/13,$B$24)+(1-$B$23)*(1-EXP(-$B$25*((8-(ROW()-ROW($B$29)+1))/7)))) -> 1.8943877 | ... O30: =$B$21+($B$22-$B$21)*($B$23*POWER((COLUMN()-COLUMN($B$29)+1)/13,$B$24)+(1-$B$23)*(1-EXP(-$B$25*((8-(ROW()-ROW($B$29)+1))/7)))) -> 2.4482338
A31: 4-6 | B31: =$B$21+($B$22-$B$21)*($B$23*POWER((COLUMN()-COLUMN($B$29)+1)/13,$B$24)+(1-$B$23)*(1-EXP(-$B$25*((8-(ROW()-ROW($B$29)+1))/7)))) -> 1.2005869 | C31: =$B$21+($B$22-$B$21)*($B$23*POWER((COLUMN()-COLUMN($B$29)+1)/13,$B$24)+(1-$B$23)*(1-EXP(-$B$25*((8-(ROW()-ROW($B$29)+1))/7)))) -> 1.2928946 | D31: =$B$21+($B$22-$B$21)*($B$23*POWER((COLUMN()-COLUMN($B$29)+1)/13,$B$24)+(1-$B$23)*(1-EXP(-$B$25*((8-(ROW()-ROW($B$29)+1))/7)))) -> 1.3852022 | E31: =$B$21+($B$22-$B$21)*($B$23*POWER((COLUMN()-COLUMN($B$29)+1)/13,$B$24)+(1-$B$23)*(1-EXP(-$B$25*((8-(ROW()-ROW($B$29)+1))/7)))) -> 1.4775099 | F31: =$B$21+($B$22-$B$21)*($B$23*POWER((COLUMN()-COLUMN($B$29)+1)/13,$B$24)+(1-$B$23)*(1-EXP(-$B$25*((8-(ROW()-ROW($B$29)+1))/7)))) -> 1.5698176 | G31: =$B$21+($B$22-$B$21)*($B$23*POWER((COLUMN()-COLUMN($B$29)+1)/13,$B$24)+(1-$B$23)*(1-EXP(-$B$25*((8-(ROW()-ROW($B$29)+1))/7)))) -> 1.6621253 | H31: =$B$21+($B$22-$B$21)*($B$23*POWER((COLUMN()-COLUMN($B$29)+1)/13,$B$24)+(1-$B$23)*(1-EXP(-$B$25*((8-(ROW()-ROW($B$29)+1))/7)))) -> 1.754433 | I31: =$B$21+($B$22-$B$21)*($B$23*POWER((COLUMN()-COLUMN($B$29)+1)/13,$B$24)+(1-$B$23)*(1-EXP(-$B$25*((8-(ROW()-ROW($B$29)+1))/7)))) -> 1.8467407 | ... O31: =$B$21+($B$22-$B$21)*($B$23*POWER((COLUMN()-COLUMN($B$29)+1)/13,$B$24)+(1-$B$23)*(1-EXP(-$B$25*((8-(ROW()-ROW($B$29)+1))/7)))) -> 2.4005869
A32: 7-14 | B32: =$B$21+($B$22-$B$21)*($B$23*POWER((COLUMN()-COLUMN($B$29)+1)/13,$B$24)+(1-$B$23)*(1-EXP(-$B$25*((8-(ROW()-ROW($B$29)+1))/7)))) -> 1.1371824 | C32: =$B$21+($B$22-$B$21)*($B$23*POWER((COLUMN()-COLUMN($B$29)+1)/13,$B$24)+(1-$B$23)*(1-EXP(-$B$25*((8-(ROW()-ROW($B$29)+1))/7)))) -> 1.2294901 | D32: =$B$21+($B$22-$B$21)*($B$23*POWER((COLUMN()-COLUMN($B$29)+1)/13,$B$24)+(1-$B$23)*(1-EXP(-$B$25*((8-(ROW()-ROW($B$29)+1))/7)))) -> 1.3217978 | E32: =$B$21+($B$22-$B$21)*($B$23*POWER((COLUMN()-COLUMN($B$29)+1)/13,$B$24)+(1-$B$23)*(1-EXP(-$B$25*((8-(ROW()-ROW($B$29)+1))/7)))) -> 1.4141055 | F32: =$B$21+($B$22-$B$21)*($B$23*POWER((COLUMN()-COLUMN($B$29)+1)/13,$B$24)+(1-$B$23)*(1-EXP(-$B$25*((8-(ROW()-ROW($B$29)+1))/7)))) -> 1.5064132 | G32: =$B$21+($B$22-$B$21)*($B$23*POWER((COLUMN()-COLUMN($B$29)+1)/13,$B$24)+(1-$B$23)*(1-EXP(-$B$25*((8-(ROW()-ROW($B$29)+1))/7)))) -> 1.5987209 | H32: =$B$21+($B$22-$B$21)*($B$23*POWER((COLUMN()-COLUMN($B$29)+1)/13,$B$24)+(1-$B$23)*(1-EXP(-$B$25*((8-(ROW()-ROW($B$29)+1))/7)))) -> 1.6910286 | I32: =$B$21+($B$22-$B$21)*($B$23*POWER((COLUMN()-COLUMN($B$29)+1)/13,$B$24)+(1-$B$23)*(1-EXP(-$B$25*((8-(ROW()-ROW($B$29)+1))/7)))) -> 1.7833363 | ... O32: =$B$21+($B$22-$B$21)*($B$23*POWER((COLUMN()-COLUMN($B$29)+1)/13,$B$24)+(1-$B$23)*(1-EXP(-$B$25*((8-(ROW()-ROW($B$29)+1))/7)))) -> 2.3371824
A33: 15-30 | B33: =$B$21+($B$22-$B$21)*($B$23*POWER((COLUMN()-COLUMN($B$29)+1)/13,$B$24)+(1-$B$23)*(1-EXP(-$B$25*((8-(ROW()-ROW($B$29)+1))/7)))) -> 1.0528094 | C33: =$B$21+($B$22-$B$21)*($B$23*POWER((COLUMN()-COLUMN($B$29)+1)/13,$B$24)+(1-$B$23)*(1-EXP(-$B$25*((8-(ROW()-ROW($B$29)+1))/7)))) -> 1.1451171 | D33: =$B$21+($B$22-$B$21)*($B$23*POWER((COLUMN()-COLUMN($B$29)+1)/13,$B$24)+(1-$B$23)*(1-EXP(-$B$25*((8-(ROW()-ROW($B$29)+1))/7)))) -> 1.2374248 | E33: =$B$21+($B$22-$B$21)*($B$23*POWER((COLUMN()-COLUMN($B$29)+1)/13,$B$24)+(1-$B$23)*(1-EXP(-$B$25*((8-(ROW()-ROW($B$29)+1))/7)))) -> 1.3297325 | F33: =$B$21+($B$22-$B$21)*($B$23*POWER((COLUMN()-COLUMN($B$29)+1)/13,$B$24)+(1-$B$23)*(1-EXP(-$B$25*((8-(ROW()-ROW($B$29)+1))/7)))) -> 1.4220402 | G33: =$B$21+($B$22-$B$21)*($B$23*POWER((COLUMN()-COLUMN($B$29)+1)/13,$B$24)+(1-$B$23)*(1-EXP(-$B$25*((8-(ROW()-ROW($B$29)+1))/7)))) -> 1.5143479 | H33: =$B$21+($B$22-$B$21)*($B$23*POWER((COLUMN()-COLUMN($B$29)+1)/13,$B$24)+(1-$B$23)*(1-EXP(-$B$25*((8-(ROW()-ROW($B$29)+1))/7)))) -> 1.6066556 | I33: =$B$21+($B$22-$B$21)*($B$23*POWER((COLUMN()-COLUMN($B$29)+1)/13,$B$24)+(1-$B$23)*(1-EXP(-$B$25*((8-(ROW()-ROW($B$29)+1))/7)))) -> 1.6989633 | ... O33: =$B$21+($B$22-$B$21)*($B$23*POWER((COLUMN()-COLUMN($B$29)+1)/13,$B$24)+(1-$B$23)*(1-EXP(-$B$25*((8-(ROW()-ROW($B$29)+1))/7)))) -> 2.2528094
A34: 31-60 | B34: =$B$21+($B$22-$B$21)*($B$23*POWER((COLUMN()-COLUMN($B$29)+1)/13,$B$24)+(1-$B$23)*(1-EXP(-$B$25*((8-(ROW()-ROW($B$29)+1))/7)))) -> 0.94053319 | C34: =$B$21+($B$22-$B$21)*($B$23*POWER((COLUMN()-COLUMN($B$29)+1)/13,$B$24)+(1-$B$23)*(1-EXP(-$B$25*((8-(ROW()-ROW($B$29)+1))/7)))) -> 1.0328409 | D34: =$B$21+($B$22-$B$21)*($B$23*POWER((COLUMN()-COLUMN($B$29)+1)/13,$B$24)+(1-$B$23)*(1-EXP(-$B$25*((8-(ROW()-ROW($B$29)+1))/7)))) -> 1.1251486 | E34: =$B$21+($B$22-$B$21)*($B$23*POWER((COLUMN()-COLUMN($B$29)+1)/13,$B$24)+(1-$B$23)*(1-EXP(-$B$25*((8-(ROW()-ROW($B$29)+1))/7)))) -> 1.2174563 | F34: =$B$21+($B$22-$B$21)*($B$23*POWER((COLUMN()-COLUMN($B$29)+1)/13,$B$24)+(1-$B$23)*(1-EXP(-$B$25*((8-(ROW()-ROW($B$29)+1))/7)))) -> 1.309764 | G34: =$B$21+($B$22-$B$21)*($B$23*POWER((COLUMN()-COLUMN($B$29)+1)/13,$B$24)+(1-$B$23)*(1-EXP(-$B$25*((8-(ROW()-ROW($B$29)+1))/7)))) -> 1.4020717 | H34: =$B$21+($B$22-$B$21)*($B$23*POWER((COLUMN()-COLUMN($B$29)+1)/13,$B$24)+(1-$B$23)*(1-EXP(-$B$25*((8-(ROW()-ROW($B$29)+1))/7)))) -> 1.4943793 | I34: =$B$21+($B$22-$B$21)*($B$23*POWER((COLUMN()-COLUMN($B$29)+1)/13,$B$24)+(1-$B$23)*(1-EXP(-$B$25*((8-(ROW()-ROW($B$29)+1))/7)))) -> 1.586687 | ... O34: =$B$21+($B$22-$B$21)*($B$23*POWER((COLUMN()-COLUMN($B$29)+1)/13,$B$24)+(1-$B$23)*(1-EXP(-$B$25*((8-(ROW()-ROW($B$29)+1))/7)))) -> 2.1405332
A35: 61-90 | B35: =$B$21+($B$22-$B$21)*($B$23*POWER((COLUMN()-COLUMN($B$29)+1)/13,$B$24)+(1-$B$23)*(1-EXP(-$B$25*((8-(ROW()-ROW($B$29)+1))/7)))) -> 0.79112586 | C35: =$B$21+($B$22-$B$21)*($B$23*POWER((COLUMN()-COLUMN($B$29)+1)/13,$B$24)+(1-$B$23)*(1-EXP(-$B$25*((8-(ROW()-ROW($B$29)+1))/7)))) -> 0.88343355 | D35: =$B$21+($B$22-$B$21)*($B$23*POWER((COLUMN()-COLUMN($B$29)+1)/13,$B$24)+(1-$B$23)*(1-EXP(-$B$25*((8-(ROW()-ROW($B$29)+1))/7)))) -> 0.97574124 | E35: =$B$21+($B$22-$B$21)*($B$23*POWER((COLUMN()-COLUMN($B$29)+1)/13,$B$24)+(1-$B$23)*(1-EXP(-$B$25*((8-(ROW()-ROW($B$29)+1))/7)))) -> 1.0680489 | F35: =$B$21+($B$22-$B$21)*($B$23*POWER((COLUMN()-COLUMN($B$29)+1)/13,$B$24)+(1-$B$23)*(1-EXP(-$B$25*((8-(ROW()-ROW($B$29)+1))/7)))) -> 1.1603566 | G35: =$B$21+($B$22-$B$21)*($B$23*POWER((COLUMN()-COLUMN($B$29)+1)/13,$B$24)+(1-$B$23)*(1-EXP(-$B$25*((8-(ROW()-ROW($B$29)+1))/7)))) -> 1.2526643 | H35: =$B$21+($B$22-$B$21)*($B$23*POWER((COLUMN()-COLUMN($B$29)+1)/13,$B$24)+(1-$B$23)*(1-EXP(-$B$25*((8-(ROW()-ROW($B$29)+1))/7)))) -> 1.344972 | I35: =$B$21+($B$22-$B$21)*($B$23*POWER((COLUMN()-COLUMN($B$29)+1)/13,$B$24)+(1-$B$23)*(1-EXP(-$B$25*((8-(ROW()-ROW($B$29)+1))/7)))) -> 1.4372797 | ... O35: =$B$21+($B$22-$B$21)*($B$23*POWER((COLUMN()-COLUMN($B$29)+1)/13,$B$24)+(1-$B$23)*(1-EXP(-$B$25*((8-(ROW()-ROW($B$29)+1))/7)))) -> 1.9911259
A36: 90-120 | B36: =$B$21+($B$22-$B$21)*($B$23*POWER((COLUMN()-COLUMN($B$29)+1)/13,$B$24)+(1-$B$23)*(1-EXP(-$B$25*((8-(ROW()-ROW($B$29)+1))/7)))) -> 0.59230769 | C36: =$B$21+($B$22-$B$21)*($B$23*POWER((COLUMN()-COLUMN($B$29)+1)/13,$B$24)+(1-$B$23)*(1-EXP(-$B$25*((8-(ROW()-ROW($B$29)+1))/7)))) -> 0.68461538 | D36: =$B$21+($B$22-$B$21)*($B$23*POWER((COLUMN()-COLUMN($B$29)+1)/13,$B$24)+(1-$B$23)*(1-EXP(-$B$25*((8-(ROW()-ROW($B$29)+1))/7)))) -> 0.77692308 | E36: =$B$21+($B$22-$B$21)*($B$23*POWER((COLUMN()-COLUMN($B$29)+1)/13,$B$24)+(1-$B$23)*(1-EXP(-$B$25*((8-(ROW()-ROW($B$29)+1))/7)))) -> 0.86923077 | F36: =$B$21+($B$22-$B$21)*($B$23*POWER((COLUMN()-COLUMN($B$29)+1)/13,$B$24)+(1-$B$23)*(1-EXP(-$B$25*((8-(ROW()-ROW($B$29)+1))/7)))) -> 0.96153846 | G36: =$B$21+($B$22-$B$21)*($B$23*POWER((COLUMN()-COLUMN($B$29)+1)/13,$B$24)+(1-$B$23)*(1-EXP(-$B$25*((8-(ROW()-ROW($B$29)+1))/7)))) -> 1.0538462 | H36: =$B$21+($B$22-$B$21)*($B$23*POWER((COLUMN()-COLUMN($B$29)+1)/13,$B$24)+(1-$B$23)*(1-EXP(-$B$25*((8-(ROW()-ROW($B$29)+1))/7)))) -> 1.1461538 | I36: =$B$21+($B$22-$B$21)*($B$23*POWER((COLUMN()-COLUMN($B$29)+1)/13,$B$24)+(1-$B$23)*(1-EXP(-$B$25*((8-(ROW()-ROW($B$29)+1))/7)))) -> 1.2384615 | ... O36: =$B$21+($B$22-$B$21)*($B$23*POWER((COLUMN()-COLUMN($B$29)+1)/13,$B$24)+(1-$B$23)*(1-EXP(-$B$25*((8-(ROW()-ROW($B$29)+1))/7)))) -> 1.7923077
B37: =B4/B13 -> 1.1972279
B40: =$B$21+($B$22-$B$21)*($B$23*POWER((COLUMN()-COLUMN($B$29)+1)/13,$B$24)+(1-$B$23)*(1-EXP(-$B$25*((8-(ROW()-ROW($B$29)+1))/7))))*B$37 -> -1.4350365
B41: =B4/B13 -> 1.1972279
B42: =B29*$B$41 -> 1.5372879 | C42: =C29*$B$41 -> 1.6478012 | D42: =D29*$B$41 -> 1.7583146 | E42: =E29*$B$41 -> 1.8688279 | F42: =F29*$B$41 -> 1.9793413 | G42: =G29*$B$41 -> 2.0898546 | H42: =H29*$B$41 -> 2.200368 | I42: =I29*$B$41 -> 2.3108813 | ... O42: =O29*$B$41 -> 2.9739614
B43: =B30*$B$41 -> 1.4944204 | C43: =C30*$B$41 -> 1.6049338 | D43: =D30*$B$41 -> 1.7154471 | E43: =E30*$B$41 -> 1.8259604 | F43: =F30*$B$41 -> 1.9364738 | G43: =G30*$B$41 -> 2.0469871 | H43: =H30*$B$41 -> 2.1575005 | I43: =I30*$B$41 -> 2.2680138 | ... O43: =O30*$B$41 -> 2.9310939
B44: =B31*$B$41 -> 1.4373761 | C44: =C31*$B$41 -> 1.5478895 | D44: =D31*$B$41 -> 1.6584028 | E44: =E31*$B$41 -> 1.7689161 | F44: =F31*$B$41 -> 1.8794295 | G44: =G31*$B$41 -> 1.9899428 | H44: =H31*$B$41 -> 2.1004562 | I44: =I31*$B$41 -> 2.2109695 | ... O44: =O31*$B$41 -> 2.8740496
B45: =B32*$B$41 -> 1.3614666 | C45: =C32*$B$41 -> 1.4719799 | D45: =D32*$B$41 -> 1.5824933 | E45: =E32*$B$41 -> 1.6930066 | F45: =F32*$B$41 -> 1.80352 | G45: =G32*$B$41 -> 1.9140333 | H45: =H32*$B$41 -> 2.0245467 | I45: =I32*$B$41 -> 2.13506 | ... O45: =O32*$B$41 -> 2.7981401
B46: =B33*$B$41 -> 1.2604528 | C46: =C33*$B$41 -> 1.3709662 | D46: =D33*$B$41 -> 1.4814795 | E46: =E33*$B$41 -> 1.5919929 | F46: =F33*$B$41 -> 1.7025062 | G46: =G33*$B$41 -> 1.8130196 | H46: =H33*$B$41 -> 1.9235329 | I46: =I33*$B$41 -> 2.0340462 | ... O46: =O33*$B$41 -> 2.6971263
...
